<?xml version="1.0" encoding="utf-8"?>
<!-- This URDF was automatically created by SolidWorks to URDF Exporter! Originally created by Stephen Brawner (brawner@gmail.com) 
     Commit Version: 1.5.1-0-g916b5db  Build Version: 1.5.7152.31018
     For more information, please see http://wiki.ros.org/sw_urdf_exporter -->
<robot
  name="Joe">
  <link
    name="base_link">
    <inertial>
      <origin
        xyz="1.11022302462516E-16 4.57966997657877E-16 -0.106987126980554"
        rpy="0 0 0" />
      <mass
        value="11.5140245979311" />
      <inertia
        ixx="0.448788498990354"
        ixy="4.02414228067302E-19"
        ixz="-1.04949529110216E-18"
        iyy="0.401603547193525"
        iyz="-4.41670292219499E-18"
        izz="0.0551686715592978" />
    </inertial>
    <visual>
      <origin
        xyz="0 0 0"
        rpy="0 0 0" />
      <geometry>
        <mesh
          filename="package://Joe/meshes/base_link.STL" />
      </geometry>
      <material
        name="">
        <color
          rgba="0.752941176470588 0.752941176470588 0.752941176470588 1" />
      </material>
    </visual>
    <collision>
      <origin
        xyz="0 0 0"
        rpy="0 0 0" />
      <geometry>
        <mesh
          filename="package://Joe/meshes/base_link.STL" />
      </geometry>
    </collision>
  </link>
  <link
    name="left_link1">
    <inertial>
      <origin
        xyz="0.020220864825567 0 -0.00451502540151849"
        rpy="0 0 0" />
      <mass
        value="0.449009050191168" />
      <inertia
        ixx="0.000189093688883389"
        ixy="-3.65460283419472E-19"
        ixz="-2.1272194111636E-07"
        iyy="0.000611349676589368"
        iyz="1.09681201569454E-20"
        izz="0.000586664398807723" />
    </inertial>
    <visual>
      <origin
        xyz="0 0 0"
        rpy="0 0 0" />
      <geometry>
        <mesh
          filename="package://Joe/meshes/left_link1.STL" />
      </geometry>
      <material
        name="">
        <color
          rgba="0.752941176470588 0.752941176470588 0.752941176470588 1" />
      </material>
    </visual>
    <collision>
      <origin
        xyz="0 0 0"
        rpy="0 0 0" />
      <geometry>
        <mesh
          filename="package://Joe/meshes/left_link1.STL" />
      </geometry>
    </collision>
  </link>
  <joint
    name="left_joint1"
    type="continuous">
    <origin
      xyz="0 0.175 0"
      rpy="3.1416 0 1.5708" />
    <parent
      link="base_link" />
    <child
      link="left_link1" />
    <axis
      xyz="0 0 1" />
  </joint>
  <link
    name="left_link2">
    <inertial>
      <origin
        xyz="-0.00188147339103562 4.41529698275156E-07 0.119240059515304"
        rpy="0 0 0" />
      <mass
        value="0.383671944787966" />
      <inertia
        ixx="0.000165197470366309"
        ixy="-2.26166332210087E-09"
        ixz="8.78294549483939E-20"
        iyy="0.000541985890564374"
        iyz="1.71933076722577E-20"
        izz="0.000551229826505679" />
    </inertial>
    <visual>
      <origin
        xyz="0 0 0"
        rpy="0 0 0" />
      <geometry>
        <mesh
          filename="package://Joe/meshes/left_link2.STL" />
      </geometry>
      <material
        name="">
        <color
          rgba="0.752941176470588 0.752941176470588 0.752941176470588 1" />
      </material>
    </visual>
    <collision>
      <origin
        xyz="0 0 0"
        rpy="0 0 0" />
      <geometry>
        <mesh
          filename="package://Joe/meshes/left_link2.STL" />
      </geometry>
    </collision>
  </link>
  <joint
    name="left_join2"
    type="continuous">
    <origin
      xyz="0 0 0"
      rpy="1.5708 0 1.5708" />
    <parent
      link="left_link1" />
    <child
      link="left_link2" />
    <axis
      xyz="0 0 1" />
  </joint>
  <link
    name="left_link3">
    <inertial>
      <origin
        xyz="-0.0362305634826249 -5.55111512312578E-17 0"
        rpy="0 0 0" />
      <mass
        value="0.0836624067435229" />
      <inertia
        ixx="8.11503042608759E-05"
        ixy="7.49197232038841E-20"
        ixz="-4.47908336914474E-21"
        iyy="8.36129101319399E-05"
        iyz="-1.26983741416935E-20"
        izz="4.48120330266361E-05" />
    </inertial>
    <visual>
      <origin
        xyz="0 0 0"
        rpy="0 0 0" />
      <geometry>
        <mesh
          filename="package://Joe/meshes/left_link3.STL" />
      </geometry>
      <material
        name="">
        <color
          rgba="0.752941176470588 0.752941176470588 0.752941176470588 1" />
      </material>
    </visual>
    <collision>
      <origin
        xyz="0 0 0"
        rpy="0 0 0" />
      <geometry>
        <mesh
          filename="package://Joe/meshes/left_link3.STL" />
      </geometry>
    </collision>
  </link>
  <joint
    name="left_joint3"
    type="continuous">
    <origin
      xyz="0 0 0.122"
      rpy="-1.5708 0 -1.5708" />
    <parent
      link="left_link2" />
    <child
      link="left_link3" />
    <axis
      xyz="0 0 1" />
  </joint>
  <link
    name="left_link4">
    <inertial>
      <origin
        xyz="0.00113226650921217 -5.20306055462605E-07 -0.203904175214239"
        rpy="0 0 0" />
      <mass
        value="0.536031842140331" />
      <inertia
        ixx="0.000352269389999399"
        ixy="-7.29005193983804E-10"
        ixz="2.63734078570941E-11"
        iyy="0.00054630845212098"
        iyz="6.37861794480233E-10"
        izz="0.000424675608858154" />
    </inertial>
    <visual>
      <origin
        xyz="0 0 0"
        rpy="0 0 0" />
      <geometry>
        <mesh
          filename="package://Joe/meshes/left_link4.STL" />
      </geometry>
      <material
        name="">
        <color
          rgba="0.752941176470588 0.752941176470588 0.752941176470588 1" />
      </material>
    </visual>
    <collision>
      <origin
        xyz="0 0 0"
        rpy="0 0 0" />
      <geometry>
        <mesh
          filename="package://Joe/meshes/left_link4.STL" />
      </geometry>
    </collision>
  </link>
  <joint
    name="left_joint4"
    type="continuous">
    <origin
      xyz="0 0 0"
      rpy="1.5708 0.0024223 1.5708" />
    <parent
      link="left_link3" />
    <child
      link="left_link4" />
    <axis
      xyz="0 0 1" />
  </joint>
  <link
    name="left_link5">
    <inertial>
      <origin
        xyz="-4.03106211854798E-07 0.122853347052059 1.11022302462516E-16"
        rpy="0 0 0" />
      <mass
        value="0.271635742603924" />
      <inertia
        ixx="0.000232339890693184"
        ixy="6.37861794468831E-10"
        ixz="1.45035651613341E-16"
        iyy="0.000117545767685688"
        iyz="1.16962914683338E-20"
        izz="0.000228408209804266" />
    </inertial>
    <visual>
      <origin
        xyz="0 0 0"
        rpy="0 0 0" />
      <geometry>
        <mesh
          filename="package://Joe/meshes/left_link5.STL" />
      </geometry>
      <material
        name="">
        <color
          rgba="0.752941176470588 0.752941176470588 0.752941176470588 1" />
      </material>
    </visual>
    <collision>
      <origin
        xyz="0 0 0"
        rpy="0 0 0" />
      <geometry>
        <mesh
          filename="package://Joe/meshes/left_link5.STL" />
      </geometry>
    </collision>
  </link>
  <joint
    name="left_joint5"
    type="continuous">
    <origin
      xyz="0 0 -0.257"
      rpy="-1.5708 0 1.5708" />
    <parent
      link="left_link4" />
    <child
      link="left_link5" />
    <axis
      xyz="0 0 1" />
  </joint>
  <link
    name="left_link6">
    <inertial>
      <origin
        xyz="1.77635683940025E-15 0 0.228662497788161"
        rpy="0 0 0" />
      <mass
        value="0.0371773964135461" />
      <inertia
        ixx="1.91147894150255E-05"
        ixy="-1.90582413132218E-21"
        ixz="1.47190091517792E-20"
        iyy="9.88466917762178E-06"
        iyz="-4.87913637271428E-22"
        izz="2.0229934027417E-05" />
    </inertial>
    <visual>
      <origin
        xyz="0 0 0"
        rpy="0 0 0" />
      <geometry>
        <mesh
          filename="package://Joe/meshes/left_link6.STL" />
      </geometry>
      <material
        name="">
        <color
          rgba="0.752941176470588 0.752941176470588 0.752941176470588 1" />
      </material>
    </visual>
    <collision>
      <origin
        xyz="0 0 0"
        rpy="0 0 0" />
      <geometry>
        <mesh
          filename="package://Joe/meshes/left_link6.STL" />
      </geometry>
    </collision>
  </link>
  <joint
    name="left_joint6"
    type="continuous">
    <origin
      xyz="0 0 0"
      rpy="-1.5708 0 0" />
    <parent
      link="left_link5" />
    <child
      link="left_link6" />
    <axis
      xyz="0 0 1" />
  </joint>
  <link
    name="left_link7">
    <inertial>
      <origin
        xyz="-2.48726896190377E-07 0.0478425504244868 -0.000809966042038424"
        rpy="0 0 0" />
      <mass
        value="0.440234064848019" />
      <inertia
        ixx="0.000890184237942202"
        ixy="-1.45223956213885E-16"
        ixz="6.37861729263452E-10"
        iyy="0.000262602167507302"
        iyz="8.05729138164508E-20"
        izz="0.000838502061395766" />
    </inertial>
    <visual>
      <origin
        xyz="0 0 0"
        rpy="0 0 0" />
      <geometry>
        <mesh
          filename="package://Joe/meshes/left_link7.STL" />
      </geometry>
      <material
        name="">
        <color
          rgba="0.752941176470588 0.752941176470588 0.752941176470588 1" />
      </material>
    </visual>
    <collision>
      <origin
        xyz="0 0 0"
        rpy="0 0 0" />
      <geometry>
        <mesh
          filename="package://Joe/meshes/left_link7.STL" />
      </geometry>
    </collision>
  </link>
  <joint
    name="left_joint7"
    type="continuous">
    <origin
      xyz="0 0 0.258"
      rpy="1.5708 0 0" />
    <parent
      link="left_link6" />
    <child
      link="left_link7" />
    <axis
      xyz="0 0 1" />
  </joint>
  <link
    name="right_link1">
    <inertial>
      <origin
        xyz="0.0202208648255669 -1.11022302462516E-16 -0.00451502540151674"
        rpy="0 0 0" />
      <mass
        value="0.449009050191167" />
      <inertia
        ixx="0.000189093688883389"
        ixy="-7.05374778682046E-20"
        ixz="-2.12721941116071E-07"
        iyy="0.000611349676589368"
        iyz="-5.15020979160932E-20"
        izz="0.000586664398807722" />
    </inertial>
    <visual>
      <origin
        xyz="0 0 0"
        rpy="0 0 0" />
      <geometry>
        <mesh
          filename="package://Joe/meshes/right_link1.STL" />
      </geometry>
      <material
        name="">
        <color
          rgba="0.752941176470588 0.752941176470588 0.752941176470588 1" />
      </material>
    </visual>
    <collision>
      <origin
        xyz="0 0 0"
        rpy="0 0 0" />
      <geometry>
        <mesh
          filename="package://Joe/meshes/right_link1.STL" />
      </geometry>
    </collision>
  </link>
  <joint
    name="right_joint1"
    type="continuous">
    <origin
      xyz="0 -0.175 0"
      rpy="3.1416 0 -1.5708" />
    <parent
      link="base_link" />
    <child
      link="right_link1" />
    <axis
      xyz="0 0 1" />
  </joint>
  <link
    name="right_link2">
    <inertial>
      <origin
        xyz="-0.0018814733910355 -4.41529699996002E-07 0.119240059515304"
        rpy="0 0 0" />
      <mass
        value="0.383671944787966" />
      <inertia
        ixx="0.000165197470366309"
        ixy="2.26166332174754E-09"
        ixz="2.15415426824174E-20"
        iyy="0.000541985890564373"
        iyz="-2.17618664274753E-20"
        izz="0.000551229826505679" />
    </inertial>
    <visual>
      <origin
        xyz="0 0 0"
        rpy="0 0 0" />
      <geometry>
        <mesh
          filename="package://Joe/meshes/right_link2.STL" />
      </geometry>
      <material
        name="">
        <color
          rgba="0.752941176470588 0.752941176470588 0.752941176470588 1" />
      </material>
    </visual>
    <collision>
      <origin
        xyz="0 0 0"
        rpy="0 0 0" />
      <geometry>
        <mesh
          filename="package://Joe/meshes/right_link2.STL" />
      </geometry>
    </collision>
  </link>
  <joint
    name="right_joint2"
    type="continuous">
    <origin
      xyz="0 0 0"
      rpy="-1.5708 0 -1.5708" />
    <parent
      link="right_link1" />
    <child
      link="right_link2" />
    <axis
      xyz="0 0 1" />
  </joint>
  <link
    name="right_link3">
    <inertial>
      <origin
        xyz="0.0362305634826248 2.77555756156289E-17 8.88178419700125E-16"
        rpy="0 0 0" />
      <mass
        value="0.0836624067435228" />
      <inertia
        ixx="8.11503042608759E-05"
        ixy="7.5894411126804E-20"
        ixz="3.90711323375774E-20"
        iyy="8.36129101319399E-05"
        iyz="2.30375526074523E-21"
        izz="4.4812033026636E-05" />
    </inertial>
    <visual>
      <origin
        xyz="0 0 0"
        rpy="0 0 0" />
      <geometry>
        <mesh
          filename="package://Joe/meshes/right_link3.STL" />
      </geometry>
      <material
        name="">
        <color
          rgba="0.752941176470588 0.752941176470588 0.752941176470588 1" />
      </material>
    </visual>
    <collision>
      <origin
        xyz="0 0 0"
        rpy="0 0 0" />
      <geometry>
        <mesh
          filename="package://Joe/meshes/right_link3.STL" />
      </geometry>
    </collision>
  </link>
  <joint
    name="right_joint3"
    type="continuous">
    <origin
      xyz="0 0 0.122"
      rpy="-1.5708 0 -1.5708" />
    <parent
      link="right_link2" />
    <child
      link="right_link3" />
    <axis
      xyz="0 0 1" />
  </joint>
  <link
    name="right_link4">
    <inertial>
      <origin
        xyz="-0.00113226650921219 -5.20306054685449E-07 -0.203904175214239"
        rpy="0 0 0" />
      <mass
        value="0.536031842140331" />
      <inertia
        ixx="0.000352269389999399"
        ixy="7.29005484181486E-10"
        ixz="-2.6373407919813E-11"
        iyy="0.00054630845212098"
        iyz="6.3786179446453E-10"
        izz="0.000424675608858154" />
    </inertial>
    <visual>
      <origin
        xyz="0 0 0"
        rpy="0 0 0" />
      <geometry>
        <mesh
          filename="package://Joe/meshes/right_link4.STL" />
      </geometry>
      <material
        name="">
        <color
          rgba="0.752941176470588 0.752941176470588 0.752941176470588 1" />
      </material>
    </visual>
    <collision>
      <origin
        xyz="0 0 0"
        rpy="0 0 0" />
      <geometry>
        <mesh
          filename="package://Joe/meshes/right_link4.STL" />
      </geometry>
    </collision>
  </link>
  <joint
    name="right_joint4"
    type="continuous">
    <origin
      xyz="0 0 0"
      rpy="1.5708 0 -1.5708" />
    <parent
      link="right_link3" />
    <child
      link="right_link4" />
    <axis
      xyz="0 0 1" />
  </joint>
  <link
    name="right_link5">
    <inertial>
      <origin
        xyz="-4.03106211410709E-07 -0.122853347052059 0"
        rpy="0 0 0" />
      <mass
        value="0.271635742603923" />
      <inertia
        ixx="0.000232339890693184"
        ixy="-6.37861794360624E-10"
        ixz="-1.45039674518219E-16"
        iyy="0.000117545767685689"
        iyz="-7.44840073702798E-21"
        izz="0.000228408209804266" />
    </inertial>
    <visual>
      <origin
        xyz="0 0 0"
        rpy="0 0 0" />
      <geometry>
        <mesh
          filename="package://Joe/meshes/right_link5.STL" />
      </geometry>
      <material
        name="">
        <color
          rgba="0.752941176470588 0.752941176470588 0.752941176470588 1" />
      </material>
    </visual>
    <collision>
      <origin
        xyz="0 0 0"
        rpy="0 0 0" />
      <geometry>
        <mesh
          filename="package://Joe/meshes/right_link5.STL" />
      </geometry>
    </collision>
  </link>
  <joint
    name="right_joint5"
    type="continuous">
    <origin
      xyz="0 0 -0.257"
      rpy="1.5708 0 1.5708" />
    <parent
      link="right_link4" />
    <child
      link="right_link5" />
    <axis
      xyz="0 0 1" />
  </joint>
  <link
    name="right_link6">
    <inertial>
      <origin
        xyz="2.33146835171283E-15 -2.77555756156289E-17 0.228662497788161"
        rpy="0 0 0" />
      <mass
        value="0.0371773964135462" />
      <inertia
        ixx="1.91147894150255E-05"
        ixy="-1.19147798135416E-20"
        ixz="8.79380577112088E-21"
        iyy="9.8846691776218E-06"
        iyz="2.82545940257756E-22"
        izz="2.0229934027417E-05" />
    </inertial>
    <visual>
      <origin
        xyz="0 0 0"
        rpy="0 0 0" />
      <geometry>
        <mesh
          filename="package://Joe/meshes/right_link6.STL" />
      </geometry>
      <material
        name="">
        <color
          rgba="0.752941176470588 0.752941176470588 0.752941176470588 1" />
      </material>
    </visual>
    <collision>
      <origin
        xyz="0 0 0"
        rpy="0 0 0" />
      <geometry>
        <mesh
          filename="package://Joe/meshes/right_link6.STL" />
      </geometry>
    </collision>
  </link>
  <joint
    name="right_joint6"
    type="continuous">
    <origin
      xyz="0 0 0"
      rpy="1.5708 0 0" />
    <parent
      link="right_link5" />
    <child
      link="right_link6" />
    <axis
      xyz="0 0 1" />
  </joint>
  <link
    name="right_link7">
    <inertial>
      <origin
        xyz="-2.48726903184782E-07 -0.0478425504244606 -0.000809966042028071"
        rpy="0 0 0" />
      <mass
        value="0.44023406484826" />
      <inertia
        ixx="0.000890184237942295"
        ixy="-1.45134024435919E-16"
        ixz="6.37861794454897E-10"
        iyy="0.000262602167507429"
        iyz="-1.15476110827972E-20"
        izz="0.000838502061395806" />
    </inertial>
    <visual>
      <origin
        xyz="0 0 0"
        rpy="0 0 0" />
      <geometry>
        <mesh
          filename="package://Joe/meshes/right_link7.STL" />
      </geometry>
      <material
        name="">
        <color
          rgba="0.752941176470588 0.752941176470588 0.752941176470588 1" />
      </material>
    </visual>
    <collision>
      <origin
        xyz="0 0 0"
        rpy="0 0 0" />
      <geometry>
        <mesh
          filename="package://Joe/meshes/right_link7.STL" />
      </geometry>
    </collision>
  </link>
  <joint
    name="right_joint7"
    type="continuous">
    <origin
      xyz="0 0 0.258"
      rpy="-1.5708 0 0" />
    <parent
      link="right_link6" />
    <child
      link="right_link7" />
    <axis
      xyz="0 0 1" />
  </joint>
</robot>