<?xml version="1.0" encoding="utf-8"?>
<!-- This URDF was automatically created by SolidWorks to URDF Exporter! Originally created by Stephen Brawner (brawner@gmail.com) 
     Commit Version: 1.5.1-0-g916b5db  Build Version: 1.5.7152.31018
     For more information, please see http://wiki.ros.org/sw_urdf_exporter -->
<robot
  name="robotmodel">
  <link
    name="body_center_link">
    <inertial>
      <origin
        xyz="0 2.64867088262122E-08 -0.104126676849772"
        rpy="0 0 0" />
      <mass
        value="12.7915143672139" />
      <inertia
        ixx="0.378733514776738"
        ixy="-7.45634698448851E-11"
        ixz="2.20516916854968E-17"
        iyy="0.332266369799227"
        iyz="4.52332668784217E-09"
        izz="0.0615432856403905" />
    </inertial>
    <visual>
      <origin
        xyz="0 0 0"
        rpy="0 0 0" />
      <geometry>
        <mesh
          filename="package://robotmodel/meshes/body_center_link.STL" />
      </geometry>
      <material
        name="">
        <color
          rgba="0.792156862745098 0.819607843137255 0.933333333333333 1" />
      </material>
    </visual>
    <collision>
      <origin
        xyz="0 0 0"
        rpy="0 0 0" />
      <geometry>
        <mesh
          filename="package://robotmodel/meshes/body_center_link.STL" />
      </geometry>
    </collision>
  </link>
  <link
    name="right_link0">
    <inertial>
      <origin
        xyz="-3.88578058618805E-16 -0.0229597483705795 0.000646096394693846"
        rpy="0 0 0" />
      <mass
        value="0.412680624747637" />
      <inertia
        ixx="0.000559131857809874"
        ixy="5.32958110609874E-18"
        ixz="-2.15087768285457E-18"
        iyy="0.0001701492977576"
        iyz="-3.71123408663025E-09"
        izz="0.000561872209013165" />
    </inertial>
    <visual>
      <origin
        xyz="0 0 0"
        rpy="0 0 0" />
      <geometry>
        <mesh
          filename="package://robotmodel/meshes/right_link0.STL" />
      </geometry>
      <material
        name="">
        <color
          rgba="0.792156862745098 0.819607843137255 0.933333333333333 1" />
      </material>
    </visual>
    <collision>
      <origin
        xyz="0 0 0"
        rpy="0 0 0" />
      <geometry>
        <mesh
          filename="package://robotmodel/meshes/right_link0.STL" />
      </geometry>
    </collision>
  </link>
  <joint
    name="right_joint0"
    type="revolute">
    <origin
      xyz="0 -0.1725 0"
      rpy="0 0 0" />
    <parent
      link="body_center_link" />
    <child
      link="right_link0" />
    <axis
      xyz="0 0 -1" />
    <limit
      lower="-2.0944"
      upper="2.0944"
      effort="0"
      velocity="0" />
  </joint>
  <link
    name="right_link1">
    <inertial>
      <origin
        xyz="-0.00157364442229338 -4.53820838255958E-07 0.120609747634796"
        rpy="0 0 0" />
      <mass
        value="0.377437989532721" />
      <inertia
        ixx="0.000162640767916205"
        ixy="2.25656207841243E-09"
        ixz="-1.17002365029649E-11"
        iyy="0.000533864581487071"
        iyz="2.44373794880928E-15"
        izz="0.000541624442500585" />
    </inertial>
    <visual>
      <origin
        xyz="0 0 0"
        rpy="0 0 0" />
      <geometry>
        <mesh
          filename="package://robotmodel/meshes/right_link1.STL" />
      </geometry>
      <material
        name="">
        <color
          rgba="0.792156862745098 0.819607843137255 0.933333333333333 1" />
      </material>
    </visual>
    <collision>
      <origin
        xyz="0 0 0"
        rpy="0 0 0" />
      <geometry>
        <mesh
          filename="package://robotmodel/meshes/right_link1.STL" />
      </geometry>
    </collision>
  </link>
  <joint
    name="right_joint1"
    type="revolute">
    <origin
      xyz="0 0 0"
      rpy="1.5708 0 0" />
    <parent
      link="right_link0" />
    <child
      link="right_link1" />
    <axis
      xyz="0 0 1" />
    <limit
      lower="-3.1416"
      upper="3.1416"
      effort="0"
      velocity="0" />
  </joint>
  <link
    name="right_link2">
    <inertial>
      <origin
        xyz="0.0377194795499745 -4.44089209850063E-16 -9.26733222966769E-07"
        rpy="0 0 0" />
      <mass
        value="0.0691597567732569" />
      <inertia
        ixx="6.67222656482244E-05"
        ixy="-3.56680790338736E-20"
        ixz="-9.53490122365195E-20"
        iyy="6.79392749473839E-05"
        iyz="-7.37532141263305E-21"
        izz="3.61673066803696E-05" />
    </inertial>
    <visual>
      <origin
        xyz="0 0 0"
        rpy="0 0 0" />
      <geometry>
        <mesh
          filename="package://robotmodel/meshes/right_link2.STL" />
      </geometry>
      <material
        name="">
        <color
          rgba="0.792156862745098 0.819607843137255 0.933333333333333 1" />
      </material>
    </visual>
    <collision>
      <origin
        xyz="0 0 0"
        rpy="0 0 0" />
      <geometry>
        <mesh
          filename="package://robotmodel/meshes/right_link2.STL" />
      </geometry>
    </collision>
  </link>
  <joint
    name="right_joint2"
    type="revolute">
    <origin
      xyz="0 0 0.12304"
      rpy="1.5708 0 -1.5708" />
    <parent
      link="right_link1" />
    <child
      link="right_link2" />
    <axis
      xyz="0 0 1" />
    <limit
      lower="-0.7854"
      upper="3.1416"
      effort="0"
      velocity="0" />
  </joint>
  <link
    name="right_link3">
    <inertial>
      <origin
        xyz="-0.000932625169110191 -0.000238522400610203 -0.190441574107348"
        rpy="0 0 0" />
      <mass
        value="0.320205690352154" />
      <inertia
        ixx="0.000179803091705952"
        ixy="2.61093134266169E-10"
        ixz="5.45586187111337E-11"
        iyy="0.000234503721195447"
        iyz="-2.73784467152018E-06"
        izz="0.000143910308996194" />
    </inertial>
    <visual>
      <origin
        xyz="0 0 0"
        rpy="0 0 0" />
      <geometry>
        <mesh
          filename="package://robotmodel/meshes/right_link3.STL" />
      </geometry>
      <material
        name="">
        <color
          rgba="0.792156862745098 0.819607843137255 0.933333333333333 1" />
      </material>
    </visual>
    <collision>
      <origin
        xyz="0 0 0"
        rpy="0 0 0" />
      <geometry>
        <mesh
          filename="package://robotmodel/meshes/right_link3.STL" />
      </geometry>
    </collision>
  </link>
  <joint
    name="right_joint3"
    type="revolute">
    <origin
      xyz="0 0 0"
      rpy="-1.5708 0 1.5708" />
    <parent
      link="right_link2" />
    <child
      link="right_link3" />
    <axis
      xyz="0 0 1" />
    <limit
      lower="-3.1416"
      upper="3.1416"
      effort="0"
      velocity="0" />
  </joint>
  <link
    name="right_link4">
    <inertial>
      <origin
        xyz="-0.00846337358017624 -0.136452976145236 -1.75282801495591E-06"
        rpy="0 0 0" />
      <mass
        value="0.166932002867665" />
      <inertia
        ixx="0.000120480530868545"
        ixy="3.52888312095154E-07"
        ixz="2.38847453703183E-09"
        iyy="6.35390339073272E-05"
        iyz="2.14772556366857E-09"
        izz="0.000138520550930089" />
    </inertial>
    <visual>
      <origin
        xyz="0 0 0"
        rpy="0 0 0" />
      <geometry>
        <mesh
          filename="package://robotmodel/meshes/right_link4.STL" />
      </geometry>
      <material
        name="">
        <color
          rgba="0.792156862745098 0.819607843137255 0.933333333333333 1" />
      </material>
    </visual>
    <collision>
      <origin
        xyz="0 0 0"
        rpy="0 0 0" />
      <geometry>
        <mesh
          filename="package://robotmodel/meshes/right_link4.STL" />
      </geometry>
    </collision>
  </link>
  <joint
    name="right_joint4"
    type="revolute">
    <origin
      xyz="0 0 -0.27"
      rpy="1.5708 0 1.5708" />
    <parent
      link="right_link3" />
    <child
      link="right_link4" />
    <axis
      xyz="0 0 1" />
    <limit
      lower="-2.3562"
      upper="2.3562"
      effort="0"
      velocity="0" />
  </joint>
  <link
    name="right_link5">
    <inertial>
      <origin
        xyz="-2.16493489801906E-15 3.10862446895044E-15 0.217966889784755"
        rpy="0 0 0" />
      <mass
        value="0.0282301710311229" />
      <inertia
        ixx="1.50504196984548E-05"
        ixy="1.85053740357491E-19"
        ixz="5.12990732742528E-20"
        iyy="6.82507232365171E-06"
        iyz="1.30841874025635E-19"
        izz="1.64366235285412E-05" />
    </inertial>
    <visual>
      <origin
        xyz="0 0 0"
        rpy="0 0 0" />
      <geometry>
        <mesh
          filename="package://robotmodel/meshes/right_link5.STL" />
      </geometry>
      <material
        name="">
        <color
          rgba="0.792156862745098 0.819607843137255 0.933333333333333 1" />
      </material>
    </visual>
    <collision>
      <origin
        xyz="0 0 0"
        rpy="0 0 0" />
      <geometry>
        <mesh
          filename="package://robotmodel/meshes/right_link5.STL" />
      </geometry>
    </collision>
  </link>
  <joint
    name="right_joint5"
    type="revolute">
    <origin
      xyz="0 0 0"
      rpy="1.5708 0 0" />
    <parent
      link="right_link4" />
    <child
      link="right_link5" />
    <axis
      xyz="0 0 1" />
    <limit
      lower="-3.1416"
      upper="3.1416"
      effort="0"
      velocity="0" />
  </joint>
  <link
    name="right_link6">
    <inertial>
      <origin
        xyz="-6.23091320095526E-07 0.00506670701069334 -0.00171023670300385"
        rpy="0 0 0" />
      <mass
        value="0.175756007124876" />
      <inertia
        ixx="0.000105527032042113"
        ixy="-1.41748590956335E-14"
        ixz="6.37858609321008E-10"
        iyy="0.000119499450919167"
        iyz="-4.98454513255084E-12"
        izz="5.32497253827401E-05" />
    </inertial>
    <visual>
      <origin
        xyz="0 0 0"
        rpy="0 0 0" />
      <geometry>
        <mesh
          filename="package://robotmodel/meshes/right_link6.STL" />
      </geometry>
      <material
        name="">
        <color
          rgba="0.792156862745098 0.819607843137255 0.933333333333333 1" />
      </material>
    </visual>
    <collision>
      <origin
        xyz="0 0 0"
        rpy="0 0 0" />
      <geometry>
        <mesh
          filename="package://robotmodel/meshes/right_link6.STL" />
      </geometry>
    </collision>
  </link>
  <joint
    name="right_joint6"
    type="revolute">
    <origin
      xyz="0 0 0.25"
      rpy="1.5708 0 0" />
    <parent
      link="right_link5" />
    <child
      link="right_link6" />
    <axis
      xyz="0 0 1" />
    <limit
      lower="-2.3562"
      upper="2.3562"
      effort="0"
      velocity="0" />
  </joint>
  <link name="right_end_effector">
   <inertial>
     <origin xyz="0 0.17 0" rpy="0 0 0"/>
     <mass value="1"/>
     <inertia ixx="1"  ixy="0"  ixz="0" iyy="1" iyz="0" izz="1" />
   </inertial>
   <visual>
     <origin xyz="0 0 0" rpy="0 0 0" />
     <geometry>
       <box size="0 0 0" />
     </geometry>
     <material name="Cyan">
       <color rgba="0 1.0 1.0 1.0"/>
     </material>
   </visual>
   <collision>
     <origin xyz="0 0 0" rpy="0 0 0"/>
     <geometry>
       <cylinder radius="1" length="0.5"/>
     </geometry>
   </collision>
  </link>

  <joint
    name="right_joint7"
    type="fixed">
    <origin
      xyz="0 0.17 0"
      rpy="1.5708 0 1.5708" />
    <parent
      link="right_link6" />
    <child
      link="right_end_effector" />
    <axis
      xyz="0 0 1" />
    <limit
      effort="30"
      velocity="1.0"
      lower="-2.3562" 
      upper="2.3562" />
  </joint>


  <link
    name="left_link0">
    <inertial>
      <origin
        xyz="2.77555756156289E-16 0.0229597483705797 0.000646096394693291"
        rpy="0 0 0" />
      <mass
        value="0.412680624747637" />
      <inertia
        ixx="0.000559131857809874"
        ixy="5.34454778797881E-18"
        ixz="2.14062976915049E-18"
        iyy="0.0001701492977576"
        iyz="3.71123408652448E-09"
        izz="0.000561872209013166" />
    </inertial>
    <visual>
      <origin
        xyz="0 0 0"
        rpy="0 0 0" />
      <geometry>
        <mesh
          filename="package://robotmodel/meshes/left_link0.STL" />
      </geometry>
      <material
        name="">
        <color
          rgba="0.792156862745098 0.819607843137255 0.933333333333333 1" />
      </material>
    </visual>
    <collision>
      <origin
        xyz="0 0 0"
        rpy="0 0 0" />
      <geometry>
        <mesh
          filename="package://robotmodel/meshes/left_link0.STL" />
      </geometry>
    </collision>
  </link>
  <joint
    name="left_joint0"
    type="revolute">
    <origin
      xyz="0 0.1725 0"
      rpy="0 0 0" />
    <parent
      link="body_center_link" />
    <child
      link="left_link0" />
    <axis
      xyz="0 0 -1" />
    <limit
      lower="-2.0944"
      upper="2.0944"
      effort="0"
      velocity="0" />
  </joint>
  <link
    name="left_link1">
    <inertial>
      <origin
        xyz="-0.00157364442229338 -4.53820839407815E-07 -0.120609747634796"
        rpy="0 0 0" />
      <mass
        value="0.377437989532721" />
      <inertia
        ixx="0.000162640767916205"
        ixy="2.25656207872992E-09"
        ixz="1.17002466826867E-11"
        iyy="0.000533864581487072"
        iyz="2.44372054807388E-15"
        izz="0.000541624442500586" />
    </inertial>
    <visual>
      <origin
        xyz="0 0 0"
        rpy="0 0 0" />
      <geometry>
        <mesh
          filename="package://robotmodel/meshes/left_link1.STL" />
      </geometry>
      <material
        name="">
        <color
          rgba="0.792156862745098 0.819607843137255 0.933333333333333 1" />
      </material>
    </visual>
    <collision>
      <origin
        xyz="0 0 0"
        rpy="0 0 0" />
      <geometry>
        <mesh
          filename="package://robotmodel/meshes/left_link1.STL" />
      </geometry>
    </collision>
  </link>
  <joint
    name="left_joint1"
    type="revolute">
    <origin
      xyz="0 0 0"
      rpy="1.5708 0 0" />
    <parent
      link="left_link0" />
    <child
      link="left_link1" />
    <axis
      xyz="0 0 1" />
    <limit
      lower="-3.1416"
      upper="3.1416"
      effort="0"
      velocity="0" />
  </joint>
  <link
    name="left_link2">
    <inertial>
      <origin
        xyz="0.0377194795499725 -8.46545056276682E-16 -9.2673322327208E-07"
        rpy="0 0 0" />
      <mass
        value="0.0691597567732569" />
      <inertia
        ixx="6.67222656482245E-05"
        ixy="4.20771702384379E-20"
        ixz="-1.15139811356126E-19"
        iyy="6.7939274947384E-05"
        iyz="1.08185033065502E-19"
        izz="3.61673066803696E-05" />
    </inertial>
    <visual>
      <origin
        xyz="0 0 0"
        rpy="0 0 0" />
      <geometry>
        <mesh
          filename="package://robotmodel/meshes/left_link2.STL" />
      </geometry>
      <material
        name="">
        <color
          rgba="0.792156862745098 0.819607843137255 0.933333333333333 1" />
      </material>
    </visual>
    <collision>
      <origin
        xyz="0 0 0"
        rpy="0 0 0" />
      <geometry>
        <mesh
          filename="package://robotmodel/meshes/left_link2.STL" />
      </geometry>
    </collision>
  </link>
  <joint
    name="left_joint2"
    type="revolute">
    <origin
      xyz="0 0 -0.12304"
      rpy="1.5708 0 -1.5708" />
    <parent
      link="left_link1" />
    <child
      link="left_link2" />
    <axis
      xyz="0 0 1" />
    <limit
      lower="-3.1416"
      upper="0.7854"
      effort="0"
      velocity="0" />
  </joint>
  <link
    name="left_link3">
    <inertial>
      <origin
        xyz="0.000932764414087559 -0.00023852248797665 -0.190441574107346"
        rpy="0 0 0" />
      <mass
        value="0.320205690352154" />
      <inertia
        ixx="0.000179803091705952"
        ixy="-1.01463045429064E-09"
        ixz="-6.46869828983057E-11"
        iyy="0.000234503721195447"
        iyz="-2.73784464316982E-06"
        izz="0.000143910308996194" />
    </inertial>
    <visual>
      <origin
        xyz="0 0 0"
        rpy="0 0 0" />
      <geometry>
        <mesh
          filename="package://robotmodel/meshes/left_link3.STL" />
      </geometry>
      <material
        name="">
        <color
          rgba="0.792156862745098 0.819607843137255 0.933333333333333 1" />
      </material>
    </visual>
    <collision>
      <origin
        xyz="0 0 0"
        rpy="0 0 0" />
      <geometry>
        <mesh
          filename="package://robotmodel/meshes/left_link3.STL" />
      </geometry>
    </collision>
  </link>
  <joint
    name="left_joint3"
    type="revolute">
    <origin
      xyz="0 0 0"
      rpy="-1.5708 0 1.5708" />
    <parent
      link="left_link2" />
    <child
      link="left_link3" />
    <axis
      xyz="0 0 1" />
    <limit
      lower="-3.1416"
      upper="3.1416"
      effort="0"
      velocity="0" />
  </joint>
  <link
    name="left_link4">
    <inertial>
      <origin
        xyz="-0.00846337358015223 -0.136452976145245 -1.75282801000154E-06"
        rpy="0 0 0" />
      <mass
        value="0.166932002867665" />
      <inertia
        ixx="0.000120480530868545"
        ixy="3.52888312095256E-07"
        ixz="2.38847453460205E-09"
        iyy="6.35390339073273E-05"
        iyz="2.14772556249002E-09"
        izz="0.000138520550930089" />
    </inertial>
    <visual>
      <origin
        xyz="0 0 0"
        rpy="0 0 0" />
      <geometry>
        <mesh
          filename="package://robotmodel/meshes/left_link4.STL" />
      </geometry>
      <material
        name="">
        <color
          rgba="0.792156862745098 0.819607843137255 0.933333333333333 1" />
      </material>
    </visual>
    <collision>
      <origin
        xyz="0 0 0"
        rpy="0 0 0" />
      <geometry>
        <mesh
          filename="package://robotmodel/meshes/left_link4.STL" />
      </geometry>
    </collision>
  </link>
  <joint
    name="left_joint4"
    type="revolute">
    <origin
      xyz="0 0 -0.27"
      rpy="1.5708 0 1.5708" />
    <parent
      link="left_link3" />
    <child
      link="left_link4" />
    <axis
      xyz="0 0 1" />
    <limit
      lower="-2.3562"
      upper="2.3562"
      effort="0"
      velocity="0" />
  </joint>
  <link
    name="left_link5">
    <inertial>
      <origin
        xyz="2.3786528302594E-14 6.52256026967279E-15 0.217966889784766"
        rpy="0 0 0" />
      <mass
        value="0.0282301710311227" />
      <inertia
        ixx="1.50504196984548E-05"
        ixy="1.1983627616889E-18"
        ixz="2.5003599683003E-20"
        iyy="6.8250723236517E-06"
        iyz="1.06812620078555E-20"
        izz="1.64366235285411E-05" />
    </inertial>
    <visual>
      <origin
        xyz="0 0 0"
        rpy="0 0 0" />
      <geometry>
        <mesh
          filename="package://robotmodel/meshes/left_link5.STL" />
      </geometry>
      <material
        name="">
        <color
          rgba="0.792156862745098 0.819607843137255 0.933333333333333 1" />
      </material>
    </visual>
    <collision>
      <origin
        xyz="0 0 0"
        rpy="0 0 0" />
      <geometry>
        <mesh
          filename="package://robotmodel/meshes/left_link5.STL" />
      </geometry>
    </collision>
  </link>
  <joint
    name="left_joint5"
    type="revolute">
    <origin
      xyz="0 0 0"
      rpy="1.5708 0 0" />
    <parent
      link="left_link4" />
    <child
      link="left_link5" />
    <axis
      xyz="0 0 1" />
    <limit
      lower="-3.1416"
      upper="3.1416"
      effort="0"
      velocity="0" />
  </joint>
  <link
    name="left_link6">
    <inertial>
      <origin
        xyz="-6.23091321483304E-07 0.00506670701069367 -0.00171023670300327"
        rpy="0 0 0" />
      <mass
        value="0.175756007124877" />
      <inertia
        ixx="0.000105527032042113"
        ixy="-1.41748498230815E-14"
        ixz="6.37858603007385E-10"
        iyy="0.000119499450919167"
        iyz="-4.98454513463385E-12"
        izz="5.32497253827401E-05" />
    </inertial>
    <visual>
      <origin
        xyz="0 0 0"
        rpy="0 0 0" />
      <geometry>
        <mesh
          filename="package://robotmodel/meshes/left_link6.STL" />
      </geometry>
      <material
        name="">
        <color
          rgba="0.792156862745098 0.819607843137255 0.933333333333333 1" />
      </material>
    </visual>
    <collision>
      <origin
        xyz="0 0 0"
        rpy="0 0 0" />
      <geometry>
        <mesh
          filename="package://robotmodel/meshes/left_link6.STL" />
      </geometry>
    </collision>
  </link>
  <joint
    name="left_joint6"
    type="revolute">
    <origin
      xyz="0 0 0.25"
      rpy="1.5708 0 0" />
    <parent
      link="left_link5" />
    <child
      link="left_link6" />
    <axis
      xyz="0 0 1" />
    <limit
      lower="-2.3562"
      upper="2.3562"
      effort="0"
      velocity="0" />
  </joint>

  <link name="left_end_effector">
   <inertial>
     <origin xyz="0 0.17 0" rpy="0 0 0"/>
     <mass value="1"/>
     <inertia ixx="1"  ixy="0"  ixz="0" iyy="1" iyz="0" izz="1" />
   </inertial>
   <visual>
     <origin xyz="0 0 0" rpy="0 0 0" />
     <geometry>
       <box size="0 0 0" />
     </geometry>
     <material name="Cyan">
       <color rgba="0 1.0 1.0 1.0"/>
     </material>
   </visual>
   <collision>
     <origin xyz="0 0 0" rpy="0 0 0"/>
     <geometry>
       <cylinder radius="1" length="0.5"/>
     </geometry>
   </collision>
  </link>

  <joint
    name="left_joint7"
    type="fixed">
    <origin
      xyz="0 0.17 0"
      rpy="1.5708 0 1.5708" />
    <parent
      link="left_link6" />
    <child
      link="left_end_effector" />
    <axis
      xyz="0 0 1" />
    <limit
      effort="30"
      velocity="1.0"
      lower="-2.3562" 
      upper="2.3562" />
  </joint>
</robot>
