<?xml version="1.0" encoding="utf-8"?>
<!-- This URDF was automatically created by SolidWorks to URDF Exporter! Originally created by Stephen Brawner (brawner@gmail.com) 
     Commit Version: 1.5.1-0-g916b5db  Build Version: 1.5.7152.31018
     For more information, please see http://wiki.ros.org/sw_urdf_exporter -->
<robot
  name="robot244">
  <link
    name="body_center_link">
    <contact>
      <rolling_friction value="100"/>
      <spinning_friction value="100"/>
      <lateral_friction value="100"/>
      <contact_cfm value="0.0"/>
      <contact_erp value="1.0"/>
      <restitution value = "0.0"/>
    </contact>
    <inertial>
      <origin
        xyz="0 2.55931592307856E-08 -0.104780250949481"
        rpy="0 0 0" />
      <mass
        value="1500" /> <!-- 13.2381123672139 -->
      <inertia
        ixx="0.397528963771738"
        ixy="-7.45634685010017E-11"
        ixz="1.92170113846497E-17"
        iyy="0.344932075161727"
        iyz="4.5233266613026E-09"
        izz="0.0682235357408905" />
    </inertial>
    <visual>
      <origin
        xyz="0 0 0"
        rpy="0 0 0" />
      <geometry>
        <mesh
          filename="package://robot244/meshes/body_center_link.STL" />
      </geometry>
      <material
        name="">
        <color
          rgba="0.792156862745098 0.819607843137255 0.933333333333333 1" />
      </material>
    </visual>
    <collision>
      <origin
        xyz="0 0 0"
        rpy="0 0 0" />
      <geometry>
        <mesh
          filename="package://robot244/meshes/body_center_link.STL" />
      </geometry>
    </collision>
  </link>
  <link
    name="right_link0">
    <inertial>
      <origin
        xyz="-4.16333634234434E-16 -0.0229597483705797 0.000646096394693235"
        rpy="0 0 0" />
      <mass
        value="0.0001" />
      <inertia
        ixx="0.000559131857809874"
        ixy="5.31417167964638E-18"
        ixz="-2.14740987308495E-18"
        iyy="0.0001701492977576"
        iyz="-3.71123408661275E-09"
        izz="0.000561872209013165" />
    </inertial>
    <visual>
      <origin
        xyz="0 0 0"
        rpy="0 0 0" />
      <geometry>
        <mesh
          filename="package://robot244/meshes/right_link0.STL" />
      </geometry>
      <material
        name="">
        <color
          rgba="0.792156862745098 0.819607843137255 0.933333333333333 1" />
      </material>
    </visual>
    <collision>
      <origin
        xyz="0 0 0"
        rpy="0 0 0" />
      <geometry>
        <mesh
          filename="package://robot244/meshes/right_link0.STL" />
      </geometry>
    </collision>
  </link>
  <joint
    name="right_joint0"
    type="revolute">
    <origin
      xyz="0 -0.177 0"
      rpy="0 0 0" />
    <parent
      link="body_center_link" />
    <child
      link="right_link0" />
    <axis
      xyz="0 0 1" />
    <limit
      lower="-2.0944"
      upper="2.0944"
      effort="0"
      velocity="0" />
  </joint>
  <link
    name="right_link1">
    <inertial>
      <origin
        xyz="-0.00157364442229344 -4.53820838922092E-07 0.120609747634796"
        rpy="0 0 0" />
      <mass
        value="0.0001" />
      <inertia
        ixx="0.000162640767916205"
        ixy="2.25656207844051E-09"
        ixz="-1.17002364921453E-11"
        iyy="0.000533864581487071"
        iyz="2.44373548682583E-15"
        izz="0.000541624442500584" />
    </inertial>
    <visual>
      <origin
        xyz="0 0 0"
        rpy="0 0 0" />
      <geometry>
        <mesh
          filename="package://robot244/meshes/right_link1.STL" />
      </geometry>
      <material
        name="">
        <color
          rgba="0.792156862745098 0.819607843137255 0.933333333333333 1" />
      </material>
    </visual>
    <collision>
      <origin
        xyz="0 0 0"
        rpy="0 0 0" />
      <geometry>
        <mesh
          filename="package://robot244/meshes/right_link1.STL" />
      </geometry>
    </collision>
  </link>
  <joint
    name="right_joint1"
    type="continuous">
    <origin
      xyz="0 0 0"
      rpy="1.5708 0 0" />
    <parent
      link="right_link0" />
    <child
      link="right_link1" />
    <axis
      xyz="0 0 1" />
    <!-- <limit
      lower="-3.1416"
      upper="3.1416"
      effort="0"
      velocity="0" /> -->
  </joint>
  <link
    name="right_link2">
    <inertial>
      <origin
        xyz="0.0377194795499749 -3.33066907387547E-16 -9.26733222911258E-07"
        rpy="0 0 0" />
      <mass
        value="0.0001" />
      <inertia
        ixx="6.67222656482244E-05"
        ixy="-3.49696552768661E-20"
        ixz="-9.40744616178301E-20"
        iyy="6.79392749473839E-05"
        iyz="2.32434821684955E-21"
        izz="3.61673066803696E-05" />
    </inertial>
    <visual>
      <origin
        xyz="0 0 0"
        rpy="0 0 0" />
      <geometry>
        <mesh
          filename="package://robot244/meshes/right_link2.STL" />
      </geometry>
      <material
        name="">
        <color
          rgba="0.792156862745098 0.819607843137255 0.933333333333333 1" />
      </material>
    </visual>
    <collision>
      <origin
        xyz="0 0 0"
        rpy="0 0 0" />
      <geometry>
        <mesh
          filename="package://robot244/meshes/right_link2.STL" />
      </geometry>
    </collision>
  </link>
  <joint
    name="right_joint2"
    type="revolute">
    <origin
      xyz="0 0 0.12304"
      rpy="1.5708 0 -1.5708" />
    <parent
      link="right_link1" />
    <child
      link="right_link2" />
    <axis
      xyz="0 0 1" />
    <limit
      lower="-0.7854"
      upper="3.1416"
      effort="0"
      velocity="0" />
  </joint>
  <link
    name="right_link3">
    <inertial>
      <origin
        xyz="-0.000932625169110191 -0.000238522400609981 -0.190441574107348"
        rpy="0 0 0" />
      <mass
        value="0.0001" />
      <inertia
        ixx="0.000179803091705952"
        ixy="2.6109313426346E-10"
        ixz="5.45586187174305E-11"
        iyy="0.000234503721195446"
        iyz="-2.73784467152018E-06"
        izz="0.000143910308996194" />
    </inertial>
    <visual>
      <origin
        xyz="0 0 0"
        rpy="0 0 0" />
      <geometry>
        <mesh
          filename="package://robot244/meshes/right_link3.STL" />
      </geometry>
      <material
        name="">
        <color
          rgba="0.792156862745098 0.819607843137255 0.933333333333333 1" />
      </material>
    </visual>
    <collision>
      <origin
        xyz="0 0 0"
        rpy="0 0 0" />
      <geometry>
        <mesh
          filename="package://robot244/meshes/right_link3.STL" />
      </geometry>
    </collision>
  </link>
  <joint
    name="right_joint3"
    type="revolute">
    <origin
      xyz="0 0 0"
      rpy="-1.5708 0 1.5708" />
    <parent
      link="right_link2" />
    <child
      link="right_link3" />
    <axis
      xyz="0 0 1" />
    <limit
      lower="-3.1416"
      upper="3.1416"
      effort="0"
      velocity="0" />
  </joint>
  <link
    name="right_link4">
    <inertial>
      <origin
        xyz="-0.00846337358017746 -0.136452976145238 -1.75282801506693E-06"
        rpy="0 0 0" />
      <mass
        value="0.0001" />
      <inertia
        ixx="0.000120480530868548"
        ixy="3.528883120971E-07"
        ixz="2.38847453670758E-09"
        iyy="6.35390339073306E-05"
        iyz="2.14772556360549E-09"
        izz="0.000138520550930095" />
    </inertial>
    <visual>
      <origin
        xyz="0 0 0"
        rpy="0 0 0" />
      <geometry>
        <mesh
          filename="package://robot244/meshes/right_link4.STL" />
      </geometry>
      <material
        name="">
        <color
          rgba="0.792156862745098 0.819607843137255 0.933333333333333 1" />
      </material>
    </visual>
    <collision>
      <origin
        xyz="0 0 0"
        rpy="0 0 0" />
      <geometry>
        <mesh
          filename="package://robot244/meshes/right_link4.STL" />
      </geometry>
    </collision>
  </link>
  <joint
    name="right_joint4"
    type="revolute">
    <origin
      xyz="0 0 -0.27"
      rpy="1.5708 0 1.5708" />
    <parent
      link="right_link3" />
    <child
      link="right_link4" />
    <axis
      xyz="0 0 1" />
    <limit
      lower="-2.3562"
      upper="2.3562"
      effort="0"
      velocity="0" />
  </joint>
  <link
    name="right_link5">
    <inertial>
      <origin
        xyz="-3.5527136788005E-15 2.44249065417534E-15 0.217966889784755"
        rpy="0 0 0" />
      <mass
        value="0.0001" />
      <inertia
        ixx="1.50504196984548E-05"
        ixy="1.84809865848485E-19"
        ixz="5.11933824382326E-20"
        iyy="6.82507232365171E-06"
        iyz="1.30831588738122E-19"
        izz="1.64366235285412E-05" />
    </inertial>
    <visual>
      <origin
        xyz="0 0 0"
        rpy="0 0 0" />
      <geometry>
        <mesh
          filename="package://robot244/meshes/right_link5.STL" />
      </geometry>
      <material
        name="">
        <color
          rgba="0.792156862745098 0.819607843137255 0.933333333333333 1" />
      </material>
    </visual>
    <collision>
      <origin
        xyz="0 0 0"
        rpy="0 0 0" />
      <geometry>
        <mesh
          filename="package://robot244/meshes/right_link5.STL" />
      </geometry>
    </collision>
  </link>
  <joint
    name="right_joint5"
    type="revolute">
    <origin
      xyz="0 0 0"
      rpy="1.5708 0 0" />
    <parent
      link="right_link4" />
    <child
      link="right_link5" />
    <axis
      xyz="0 0 1" />
    <limit
      lower="-3.1416"
      upper="3.1416"
      effort="0"
      velocity="0" />
  </joint>
  <link
    name="right_link6">
    <inertial>
      <origin
        xyz="-6.23091322426994E-07 0.00506670701069389 -0.0017102367030033"
        rpy="0 0 0" />
      <mass
        value="0.0001" />
      <inertia
        ixx="0.000105527032042113"
        ixy="-1.41748522287003E-14"
        ixz="6.37858609316103E-10"
        iyy="0.000119499450919167"
        iyz="-4.98454515367906E-12"
        izz="5.324972538274E-05" />
    </inertial>
    <visual>
      <origin
        xyz="0 0 0"
        rpy="0 0 0" />
      <geometry>
        <mesh
          filename="package://robot244/meshes/right_link6.STL" />
      </geometry>
      <material
        name="">
        <color
          rgba="0.792156862745098 0.819607843137255 0.933333333333333 1" />
      </material>
    </visual>
    <collision>
      <origin
        xyz="0 0 0"
        rpy="0 0 0" />
      <geometry>
        <mesh
          filename="package://robot244/meshes/right_link6.STL" />
      </geometry>
    </collision>
  </link>
  <joint
    name="right_joint6"
    type="revolute">
    <origin
      xyz="0 0 0.25"
      rpy="1.5708 0 0" />
    <parent
      link="right_link5" />
    <child
      link="right_link6" />
    <axis
      xyz="0 0 1" />
    <limit
      lower="-2.3562"
      upper="2.3562"
      effort="0"
      velocity="0" />
  </joint>
  
  <link name="right_end_effector">
   <inertial>
     <origin xyz="0 0.17 0" rpy="0 0 0"/>
     <mass value="0.0001"/>
     <inertia ixx="1"  ixy="0"  ixz="0" iyy="1" iyz="0" izz="1" />
   </inertial>
   <visual>
     <origin xyz="0 0 0" rpy="0 0 0" />
     <geometry>
       <box size="0 0 0" />
     </geometry>
     <material name="Cyan">
       <color rgba="0 1.0 1.0 1.0"/>
     </material>
   </visual>
   <collision>
     <origin xyz="0 0 0" rpy="0 0 0"/>
     <geometry>
       <cylinder radius="1" length="0.5"/>
     </geometry>
   </collision>
  </link>

  <joint
    name="right_joint7"
    type="fixed">
    <origin
      xyz="0 0.17 0"
      rpy="1.5708 0 1.5708" />
    <parent
      link="right_link6" />
    <child
      link="right_end_effector" />
    <axis
      xyz="0 0 1" />
    <limit
      effort="30"
      velocity="1.0"
      lower="-2.3562" 
      upper="2.3562" />
  </joint>

  <link
    name="left_link0">
    <inertial>
      <origin
        xyz="3.05311331771918E-16 0.0229597483705796 0.000646096394693318"
        rpy="0 0 0" />
      <mass
        value="0.0001" />
      <inertia
        ixx="0.000559131857809874"
        ixy="5.34602407401115E-18"
        ixz="2.13946745336065E-18"
        iyy="0.0001701492977576"
        iyz="3.71123408652561E-09"
        izz="0.000561872209013166" />
    </inertial>
    <visual>
      <origin
        xyz="0 0 0"
        rpy="0 0 0" />
      <geometry>
        <mesh
          filename="package://robot244/meshes/left_link0.STL" />
      </geometry>
      <material
        name="">
        <color
          rgba="0.792156862745098 0.819607843137255 0.933333333333333 1" />
      </material>
    </visual>
    <collision>
      <origin
        xyz="0 0 0"
        rpy="0 0 0" />
      <geometry>
        <mesh
          filename="package://robot244/meshes/left_link0.STL" />
      </geometry>
    </collision>
  </link>
  <joint
    name="left_joint0"
    type="revolute">
    <origin
      xyz="0 0.177 0"
      rpy="0 0 0" />
    <parent
      link="body_center_link" />
    <child
      link="left_link0" />
    <axis
      xyz="0 0 1" />
    <limit
      lower="-2.0944"
      upper="2.0944"
      effort="0"
      velocity="0" />
  </joint>
  <link
    name="left_link1">
    <inertial>
      <origin
        xyz="-0.00157364442229338 -4.53820839407815E-07 -0.120609747634796"
        rpy="0 0 0" />
      <mass
        value="0.0001" />
      <inertia
        ixx="0.000162640767916205"
        ixy="2.25656207872941E-09"
        ixz="1.17002466793366E-11"
        iyy="0.000533864581487072"
        iyz="2.4437203611178E-15"
        izz="0.000541624442500586" />
    </inertial>
    <visual>
      <origin
        xyz="0 0 0"
        rpy="0 0 0" />
      <geometry>
        <mesh
          filename="package://robot244/meshes/left_link1.STL" />
      </geometry>
      <material
        name="">
        <color
          rgba="0.792156862745098 0.819607843137255 0.933333333333333 1" />
      </material>
    </visual>
    <collision>
      <origin
        xyz="0 0 0"
        rpy="0 0 0" />
      <geometry>
        <mesh
          filename="package://robot244/meshes/left_link1.STL" />
      </geometry>
    </collision>
  </link>
  <joint
    name="left_joint1"
    type="revolute">
    <origin
      xyz="0 0 0"
      rpy="1.5708 0 0" />
    <parent
      link="left_link0" />
    <child
      link="left_link1" />
    <axis
      xyz="0 0 1" />
    <limit
      lower="-3.1416"
      upper="3.1416"
      effort="0"
      velocity="0" />
  </joint>
  <link
    name="left_link2">
    <inertial>
      <origin
        xyz="0.0377194795499725 -8.46545056276682E-16 -9.26733223244325E-07"
        rpy="0 0 0" />
      <mass
        value="0.0001" />
      <inertia
        ixx="6.67222656482245E-05"
        ixy="4.19991449123442E-20"
        ixz="-1.15125008913129E-19"
        iyy="6.7939274947384E-05"
        iyz="1.08178567267325E-19"
        izz="3.61673066803696E-05" />
    </inertial>
    <visual>
      <origin
        xyz="0 0 0"
        rpy="0 0 0" />
      <geometry>
        <mesh
          filename="package://robot244/meshes/left_link2.STL" />
      </geometry>
      <material
        name="">
        <color
          rgba="0.792156862745098 0.819607843137255 0.933333333333333 1" />
      </material>
    </visual>
    <collision>
      <origin
        xyz="0 0 0"
        rpy="0 0 0" />
      <geometry>
        <mesh
          filename="package://robot244/meshes/left_link2.STL" />
      </geometry>
    </collision>
  </link>
  <joint
    name="left_joint2"
    type="revolute">
    <origin
      xyz="0 0 -0.12304"
      rpy="1.5708 0 -1.5708" />
    <parent
      link="left_link1" />
    <child
      link="left_link2" />
    <axis
      xyz="0 0 1" />
    <limit
      lower="-3.1416"
      upper="0.7854"
      effort="0"
      velocity="0" />
  </joint>
  <link
    name="left_link3">
    <inertial>
      <origin
        xyz="0.000932764414087461 -0.000238522487976539 -0.190441574107346"
        rpy="0 0 0" />
      <mass
        value="0.0001" />
      <inertia
        ixx="0.000179803091705952"
        ixy="-1.01463045429158E-09"
        ixz="-6.46869828977104E-11"
        iyy="0.000234503721195447"
        iyz="-2.73784464316981E-06"
        izz="0.000143910308996194" />
    </inertial>
    <visual>
      <origin
        xyz="0 0 0"
        rpy="0 0 0" />
      <geometry>
        <mesh
          filename="package://robot244/meshes/left_link3.STL" />
      </geometry>
      <material
        name="">
        <color
          rgba="0.792156862745098 0.819607843137255 0.933333333333333 1" />
      </material>
    </visual>
    <collision>
      <origin
        xyz="0 0 0"
        rpy="0 0 0" />
      <geometry>
        <mesh
          filename="package://robot244/meshes/left_link3.STL" />
      </geometry>
    </collision>
  </link>
  <joint
    name="left_joint3"
    type="revolute">
    <origin
      xyz="0 0 0"
      rpy="-1.5708 0 1.5708" />
    <parent
      link="left_link2" />
    <child
      link="left_link3" />
    <axis
      xyz="0 0 1" />
    <limit
      lower="-3.1416"
      upper="3.1416"
      effort="0"
      velocity="0" />
  </joint>
  <link
    name="left_link4">
    <inertial>
      <origin
        xyz="-0.00846337358015314 -0.136452976145246 -1.75282801005705E-06"
        rpy="0 0 0" />
      <mass
        value="0.0001" />
      <inertia
        ixx="0.000120480530868548"
        ixy="3.52888312097181E-07"
        ixz="2.38847453429067E-09"
        iyy="6.35390339073307E-05"
        iyz="2.14772556242787E-09"
        izz="0.000138520550930095" />
    </inertial>
    <visual>
      <origin
        xyz="0 0 0"
        rpy="0 0 0" />
      <geometry>
        <mesh
          filename="package://robot244/meshes/left_link4.STL" />
      </geometry>
      <material
        name="">
        <color
          rgba="0.792156862745098 0.819607843137255 0.933333333333333 1" />
      </material>
    </visual>
    <collision>
      <origin
        xyz="0 0 0"
        rpy="0 0 0" />
      <geometry>
        <mesh
          filename="package://robot244/meshes/left_link4.STL" />
      </geometry>
    </collision>
  </link>
  <joint
    name="left_joint4"
    type="revolute">
    <origin
      xyz="0 0 -0.27"
      rpy="1.5708 0 1.5708" />
    <parent
      link="left_link3" />
    <child
      link="left_link4" />
    <axis
      xyz="0 0 1" />
    <limit
      lower="-2.3562"
      upper="2.3562"
      effort="0"
      velocity="0" />
  </joint>
  <link
    name="left_link5">
    <inertial>
      <origin
        xyz="2.38420394538252E-14 6.36990460378684E-15 0.217966889784766"
        rpy="0 0 0" />
      <mass
        value="0.0001" />
      <inertia
        ixx="1.50504196984548E-05"
        ixy="1.19835659134431E-18"
        ixz="2.49747049896816E-20"
        iyy="6.8250723236517E-06"
        iyz="1.06879186303917E-20"
        izz="1.64366235285411E-05" />
    </inertial>
    <visual>
      <origin
        xyz="0 0 0"
        rpy="0 0 0" />
      <geometry>
        <mesh
          filename="package://robot244/meshes/left_link5.STL" />
      </geometry>
      <material
        name="">
        <color
          rgba="0.792156862745098 0.819607843137255 0.933333333333333 1" />
      </material>
    </visual>
    <collision>
      <origin
        xyz="0 0 0"
        rpy="0 0 0" />
      <geometry>
        <mesh
          filename="package://robot244/meshes/left_link5.STL" />
      </geometry>
    </collision>
  </link>
  <joint
    name="left_joint5"
    type="revolute">
    <origin
      xyz="0 0 0"
      rpy="1.5708 0 0" />
    <parent
      link="left_link4" />
    <child
      link="left_link5" />
    <axis
      xyz="0 0 1" />
    <limit
      lower="-3.1416"
      upper="3.1416"
      effort="0"
      velocity="0" />
  </joint>
  <link
    name="left_link6">
    <inertial>
      <origin
        xyz="-6.23091321455549E-07 0.00506670701069356 -0.00171023670300308"
        rpy="0 0 0" />
      <mass
        value="0.0001" />
      <inertia
        ixx="0.000105527032042113"
        ixy="-1.41748518797633E-14"
        ixz="6.37858603006567E-10"
        iyy="0.000119499450919167"
        iyz="-4.98454512963613E-12"
        izz="5.32497253827401E-05" />
    </inertial>
    <visual>
      <origin
        xyz="0 0 0"
        rpy="0 0 0" />
      <geometry>
        <mesh
          filename="package://robot244/meshes/left_link6.STL" />
      </geometry>
      <material
        name="">
        <color
          rgba="0.792156862745098 0.819607843137255 0.933333333333333 1" />
      </material>
    </visual>
    <collision>
      <origin
        xyz="0 0 0"
        rpy="0 0 0" />
      <geometry>
        <mesh
          filename="package://robot244/meshes/left_link6.STL" />
      </geometry>
    </collision>
  </link>
  <joint
    name="left_joint6"
    type="revolute">
    <origin
      xyz="0 0 0.25"
      rpy="1.5708 0 0" />
    <parent
      link="left_link5" />
    <child
      link="left_link6" />
    <axis
      xyz="0 0 1" />
    <limit
      lower="-2.3562"
      upper="2.3562"
      effort="0"
      velocity="0" />
  </joint>

  <link name="left_end_effector">
   <inertial>
     <origin xyz="0 0.17 0" rpy="0 0 0"/>
     <mass value="0.0001"/>
     <inertia ixx="1"  ixy="0"  ixz="0" iyy="1" iyz="0" izz="1" />
   </inertial>
   <visual>
     <origin xyz="0 0 0" rpy="0 0 0" />
     <geometry>
       <box size="0 0 0" />
     </geometry>
     <material name="Cyan">
       <color rgba="0 1.0 1.0 1.0"/>
     </material>
   </visual>
   <collision>
     <origin xyz="0 0 0" rpy="0 0 0"/>
     <geometry>
       <cylinder radius="1" length="0.5"/>
     </geometry>
   </collision>
  </link>

  <joint
    name="left_joint7"
    type="fixed">
    <origin
      xyz="0 0.17 0"
      rpy="1.5708 0 1.5708" />
    <parent
      link="left_link6" />
    <child
      link="left_end_effector" />
    <axis
      xyz="0 0 1" />
    <limit
      effort="30"
      velocity="1.0"
      lower="-2.3562" 
      upper="2.3562" />
  </joint>
</robot>
